2022-05-08 15:05:36,999 : INFO : Start of Prediction
2022-05-08 15:05:37,003 : INFO : run_id:2022-05-08_150536_376559429
2022-05-08 15:05:37,003 : INFO : Start of Data Load, validation and transformation
2022-05-08 15:05:37,003 : INFO : Start of Archiving Old Rejected Files...
2022-05-08 15:05:37,003 : INFO : End of Archiving Old Rejected Files...
2022-05-08 15:05:37,003 : INFO : Start of Archiving Old Validated Files...
2022-05-08 15:05:37,003 : INFO : End of Archiving Old Validated Files...
2022-05-08 15:05:37,003 : INFO : Start of Archiving Old Processed Files...
2022-05-08 15:05:37,005 : INFO : End of Archiving Old Processed Files...
2022-05-08 15:05:37,005 : INFO : Start of Archiving Old Result Files...
2022-05-08 15:05:37,022 : INFO : End of Archiving Old Result Files...
2022-05-08 15:05:37,023 : INFO : Start of Reading values From Schema...
2022-05-08 15:05:37,024 : INFO : End of Reading values From Schema...
2022-05-08 15:05:37,024 : INFO : Start of Validating Column Length...
2022-05-08 15:05:37,038 : INFO : End of Validating Column Length...
2022-05-08 15:05:37,038 : INFO : Start of Validating Missing Values...
2022-05-08 15:05:37,054 : INFO : End of Validating Missing Values...
2022-05-08 15:05:37,054 : INFO : Start of Replacing Missing Values with NULL...
2022-05-08 15:05:37,071 : INFO : predict3.csv: File Transformed successfully!!
2022-05-08 15:05:37,071 : INFO : End of Replacing Missing Values with NULL...
2022-05-08 15:05:37,071 : INFO : Start of creating Table
2022-05-08 15:05:37,071 : INFO : Opened prediction database successfully
2022-05-08 15:05:37,071 : INFO : Exception raise while creating table: near "EXITS": syntax error 
2022-05-08 15:05:37,071 : ERROR : Unsuccessful End of Data Load, validation and transformation
Traceback (most recent call last):
  File "D:\Shubham\Project\End_to_End_project_emp_retention\apps\ingestion\load_validate.py", line 223, in validate_predictset
    self.dbOperation.create_table('prediction', 'prediction_raw_data_t', column_names)
  File "D:\Shubham\Project\End_to_End_project_emp_retention\apps\database\database_operation.py", line 56, in create_table
    raise e
  File "D:\Shubham\Project\End_to_End_project_emp_retention\apps\database\database_operation.py", line 33, in create_table
    conn.execute("DROP TABLE IF EXITS '"+table_name+"';")
sqlite3.OperationalError: near "EXITS": syntax error
2022-05-08 15:05:37,086 : ERROR : Unsuccessful End of Prediction
Traceback (most recent call last):
  File "D:\Shubham\Project\End_to_End_project_emp_retention\apps\ingestion\load_validate.py", line 223, in validate_predictset
    self.dbOperation.create_table('prediction', 'prediction_raw_data_t', column_names)
  File "D:\Shubham\Project\End_to_End_project_emp_retention\apps\database\database_operation.py", line 56, in create_table
    raise e
  File "D:\Shubham\Project\End_to_End_project_emp_retention\apps\database\database_operation.py", line 33, in create_table
    conn.execute("DROP TABLE IF EXITS '"+table_name+"';")
sqlite3.OperationalError: near "EXITS": syntax error

During handling of the above exception, another exception occurred:

Traceback (most recent call last):
  File "D:\Shubham\Project\End_to_End_project_emp_retention\apps\prediction\predict_model.py", line 24, in batch_predict_from_model
    self.loadValidate.validate_predictset()
  File "D:\Shubham\Project\End_to_End_project_emp_retention\apps\ingestion\load_validate.py", line 233, in validate_predictset
    raise Exception
Exception
